Workbook

Sheet Summary
A1: Equity risk dashboard
A2: Data source: yfinance+fred
A3: 10-stock portfolio, last 504 trading days. Change weights on the Inputs tab.
A5: Key metric | B5: Value
A6: Annualised return | B6: =Risk!B7
A7: Annualised volatility | B7: =Risk!B8
A8: Sharpe ratio | B8: =Risk!B9
A9: Maximum drawdown | B9: =Risk!B12
A10: Beta vs SPY | B10: =Risk!B13
A11: 1-day historical VaR ($) | B11: =Risk!B17
A12: 1-day CVaR ($) | B12: =Risk!B18
A13: Horizon parametric VaR ($) | B13: =Risk!B19
A15: Weights check | B15: =Inputs!E20

Sheet Inputs
A1: Portfolio inputs
A2: Data source: yfinance+fred
A3: Portfolio value ($) | B3: 1000000 | C3: Assumption: notional size for $ risk numbers
A4: VaR confidence level | B4: 0.95 | C4: Assumption: 95% is a common desk convention
A5: Risk-free rate (annual) | B5: 0.03 | C5: Assumption: flat rate used in Sharpe ratio
A6: Trading days per year | B6: 252 | C6: Convention
A7: VaR horizon (days) | B7: 10 | C7: Used for the square-root-of-time VaR
A9: Ticker | B9: Name | C9: Sector | D9: Weight
A10: AAPL | B10: Apple | C10: Technology | D10: 0.1
A11: MSFT | B11: Microsoft | C11: Technology | D11: 0.1
A12: JPM | B12: JPMorgan Chase | C12: Financials | D12: 0.1
A13: JNJ | B13: Johnson & Johnson | C13: Health Care | D13: 0.1
A14: XOM | B14: Exxon Mobil | C14: Energy | D14: 0.1
A15: PG | B15: Procter & Gamble | C15: Consumer Staples | D15: 0.1
A16: AMZN | B16: Amazon | C16: Consumer Discretionary | D16: 0.1
A17: NEE | B17: NextEra Energy | C17: Utilities | D17: 0.1
A18: CAT | B18: Caterpillar | C18: Industrials | D18: 0.1
A19: VZ | B19: Verizon | C19: Communication | D19: 0.1
C20: Total | D20: =SUM(D10:D19) | E20: =IF(ABS(D20-1)<0.0001,"OK","Weights must sum to 100%")
A22: Legend
A23: Blue text = hardcoded input or data
A24: Black text = formula
A25: Green text = link from another sheet
A26: Yellow fill = cells to change (weights, portfolio value, etc.)
A27: Tip: try Data > Solver to maximise the Sharpe ratio on Risk!B9 by changing the weights.

Sheet Returns
A1: Daily simple returns, last 504 trading days
A2: Source: daily_returns view in the SQL database (adjusted close). Data in blue.
A3: Weight | B3: =Inputs!D10 | C3: =Inputs!D11 | D3: =Inputs!D12 | E3: =Inputs!D13 | F3: =Inputs!D14 | G3: =Inputs!D15 | H3: =Inputs!D16 | I3: =Inputs!D17 | J3: =Inputs!D18 | K3: =Inputs!D19
A5: Date | B5: =Inputs!A10 | C5: =Inputs!A11 | D5: =Inputs!A12 | E5: =Inputs!A13 | F5: =Inputs!A14 | G5: =Inputs!A15 | H5: =Inputs!A16 | I5: =Inputs!A17 | J5: =Inputs!A18 | K5: =Inputs!A19 | L5: SPY | M5: Portfolio | N5: Growth of 1 | O5: Running max | P5: Drawdown
A6: 2023-12-27 | B6: 0.00051794747 | C6: -0.001574677 | D6: 0.005998069 | E6: 0.0013448312 | F6: -0.0046994073 | G6: 0.00082214271 | H6: -0.00045634132 | I6: 0.0061452195 | J6: 0.0084224547 | K6: -0.0045359071 | L6: 0.0018081516 | M6: =SUMPRODUCT($B$3:$K$3,B6:K6) | N6: =1+M6 | O6: =MAX(1,N6) | P6: =N6/O6-1
A7: 2023-12-28 | B7: 0.002226325 | C7: 0.0032346455 | D7: 0.0053127016 | E7: 0.0014712334 | F7: -0.01446016 | G7: -0.0022592599 | H7: 0.00026091396 | I7: 0.0072630304 | J7: -0.0041592181 | K7: 0.0048243751 | L7: 0.00037765807 | M7: =SUMPRODUCT($B$3:$K$3,B7:K7) | N7: =N6*(1+M7) | O7: =MAX(O6,N7) | P7: =N7/O7-1
A8: 2023-12-29 | B8: -0.0054240372 | C8: 0.0020251434 | D8: -0.0011741502 | E8: 0.0010217389 | F8: -0.0020958559 | G8: 0.005558136 | H8: -0.0093884626 | I8: -0.0045885951 | J8: -0.0040758948 | K8: 0.0056016681 | L8: -0.0028949686 | M8: =SUMPRODUCT($B$3:$K$3,B8:K8) | N8: =N7*(1+M8) | O8: =MAX(O7,N8) | P8: =N8/O8-1
A9: 2024-01-02 | B9: -0.035786765 | C9: -0.013748498 | D9: 0.01164011 | E9: 0.020607647 | F9: 0.023804729 | G9: 0.015013106 | H9: -0.01322897 | I9: 0.013664774 | J9: -0.010010964 | K9: 0.031299824 | L9: -0.0055963563 | M9: =SUMPRODUCT($B$3:$K$3,B9:K9) | N9: =N8*(1+M9) | O9: =MAX(O8,N9) | P9: =N9/O9-1
A10: 2024-01-03 | B10: -0.0074873764 | C10: -0.00072789776 | D10: -0.0043585045 | E10: 0.0062508244 | F10: 0.0084017264 | G10: -0.0060507674 | H10: -0.0097378212 | I10: 0.0068215424 | J10: -0.028731627 | K10: 0.0072014768 | L10: -0.0081666897 | M10: =SUMPRODUCT($B$3:$K$3,B10:K10) | N10: =N9*(1+M10) | O10: =MAX(O9,N10) | P10: =N10/O10-1
A11: 2024-01-04 | B11: -0.012700291 | C11: -0.0071778037 | D11: 0.0066362148 | E11: -0.0021119695 | F11: -0.008719225 | G11: 0.0054786976 | H11: -0.026267892 | I11: -0.0030650912 | J11: 0.006331298 | K11: 0.0053628396 | L11: -0.0032210737 | M11: =SUMPRODUCT($B$3:$K$3,B11:K11) | N11: =N10*(1+M11) | O11: =MAX(O10,N11) | P11: =N11/O11-1
A12: 2024-01-05 | B12: -0.0040128001 | C12: -0.00051632222 | D12: 0.0050171752 | E12: 0.0031126221 | F12: 0.0030297406 | G12: -0.0082742171 | H12: 0.0046344202 | I12: 0.0045308816 | J12: 0.0098917899 | K12: 0.021081694 | L12: 0.0013696301 | M12: =SUMPRODUCT($B$3:$K$3,B12:K12) | N12: =N11*(1+M12) | O12: =MAX(O11,N12) | P12: =N12/O12-1
A13: 2024-01-08 | B13: 0.024174658 | C13: 0.018871727 | D13: -0.00145102 | E13: 0.002482371 | F13: -0.016662017 | G13: 0.008614844 | H13: 0.026576704 | I13: 0.013530803 | J13: 0.01149057 | K13: -0.002487407 | L13: 0.014276008 | M13: =SUMPRODUCT($B$3:$K$3,B13:K13) | N13: =N12*(1+M13) | O13: =MAX(O12,N13) | P13: =N13/O13-1
A14: 2024-01-09 | B14: -0.0022635366 | C14: 0.0029356451 | D14: -0.007906201 | E14: 0.00061926013 | F14: -0.01238596 | G14: 0.0041024457 | H14: 0.015224607 | I14: -0.014462804 | J14: 0.00013696453 | K14: -0.010016356 | L14: -0.0015170438 | M14: =SUMPRODUCT($B$3:$K$3,B14:K14) | N14: =N13*(1+M14) | O14: =MAX(O13,N14) | P14: =N14/O14-1
A15: 2024-01-10 | B15: 0.0056715544 | C15: 0.01857405 | D15: 0.0021095237 | E15: 0.0014847742 | F15: -0.0098323859 | G15: 0.0042864846 | H15: 0.015590941 | I15: 0.0043542373 | J15: 0.003626571 | K15: 0.0010245872 | L15: 0.0056554089 | M15: =SUMPRODUCT($B$3:$K$3,B15:K15) | N15: =N14*(1+M15) | O15: =MAX(O14,N15) | P15: =N15/O15-1
A16: 2024-01-11 | B16: -0.0032225162 | C16: 0.0048593552 | D16: -0.004210166 | E16: -0.004448126 | F16: -0.00020272769 | G16: 0.0038015457 | H16: 0.0094321017 | I16: -0.025048157 | J16: -0.0043977354 | K16: -0.030194444 | L16: -0.00044064304 | M16: =SUMPRODUCT($B$3:$K$3,B16:K16) | N16: =N15*(1+M16) | O16: =MAX(O15,N16) | P16: =N16/O16-1
A17: 2024-01-12 | B17: 0.0017780806 | C17: 0.0099835407 | D17: -0.0073399704 | E17: 0.0076949689 | F17: 0.012972468 | G17: 0.00059799379 | H17: -0.0036086969 | I17: 0.005269969 | J17: -0.005649451 | K17: 0.017414257 | L17: 0.00069271596 | M17: =SUMPRODUCT($B$3:$K$3,B17:K17) | N17: =N16*(1+M17) | O17: =MAX(O16,N17) | P17: =N17/O17-1
A18: 2024-01-16 | B18: -0.012317143 | C18: 0.0046336009 | D18: -0.0062701248 | E18: -0.011515728 | F18: -0.022611097 | G18: -0.0053786187 | H18: -0.0094424492 | I18: -0.011303933 | J18: -0.010950037 | K18: 0.018931451 | L18: -0.0036711672 | M18: =SUMPRODUCT($B$3:$K$3,B18:K18) | N18: =N17*(1+M18) | O18: =MAX(O17,N18) | P18: =N18/O18-1
... A509: 2025-12-30 | B509: -0.0024840667 | C509: 0.00078016881 | D509: -0.0010192056 | E509: -0.0031316936 | F509: 0.0038165166 | G509: -0.0035970125 | H509: 0.0019821237 | I509: 0.0032390672 | J509: -0.0021085997 | K509: 0.0054347762 | L509: -0.0012212056 | M509: =SUMPRODUCT($B$3:$K$3,B509:K509) | N509: =N508*(1+M509) | O509: =MAX(O508,N509) | P509: =N509/O509-1

Sheet Risk
A1: Portfolio risk
A2: Data source: yfinance+fred
A4: Metric | B4: Value | C4: Note
A5: Observations | B5: =COUNT(Returns!$M$6:$M$509) | C5: Trading days in the sample
A6: Mean daily return | B6: =AVERAGE(Returns!$M$6:$M$509)
A7: Annualised return | B7: =B6*Inputs!$B$6 | C7: Arithmetic: mean daily x days per year
A8: Annualised volatility | B8: =STDEV(Returns!$M$6:$M$509)*SQRT(Inputs!$B$6) | C8: Sample st. dev. x sqrt(days)
A9: Sharpe ratio | B9: =(B7-Inputs!$B$5)/B8 | C9: Uses the risk-free rate on Inputs
A10: Best day | B10: =MAX(Returns!$M$6:$M$509)
A11: Worst day | B11: =MIN(Returns!$M$6:$M$509)
A12: Maximum drawdown | B12: =MIN(Returns!$P$6:$P$509) | C12: Peak to trough, from Returns tab
A13: Beta vs SPY | B13: =SLOPE(Returns!$M$6:$M$509,Returns!$L$6:$L$509) | C13: Regression slope on daily returns
A14: 1-day historical VaR | B14: =-PERCENTILE(Returns!$M$6:$M$509,1-Inputs!$B$4) | C14: Loss not exceeded at the confidence level
A15: 1-day parametric VaR | B15: =-(B6+NORMSINV(1-Inputs!$B$4)*STDEV(Returns!$M$6:$M$509)) | C15: Assumes normal returns
A16: 1-day CVaR (expected shortfall) | B16: =-AVERAGEIF(Returns!$M$6:$M$509,"<="&-B14) | C16: Average loss on days beyond the historical VaR
A17: 1-day historical VaR ($) | B17: =B14*Inputs!$B$3
A18: 1-day CVaR ($) | B18: =B16*Inputs!$B$3
A19: Horizon parametric VaR ($) | B19: =B15*SQRT(Inputs!$B$7)*Inputs!$B$3 | C19: Square-root-of-time, assumes i.i.d. returns
A20: Days worse than hist. VaR | B20: =COUNTIF(Returns!$M$6:$M$509,"<"&-B14) | C20: Should be roughly (1 - confidence) x observations
A23: Per-stock statistics
A24: Ticker | B24: Sector | C24: Weight | D24: Ann. return | E24: Ann. volatility | F24: Beta (Excel, sample) | G24: Beta (SQL, full history) | H24: Correlation to SPY
A25: =Inputs!A10 | B25: =Inputs!C10 | C25: =Inputs!D10 | D25: =AVERAGE(Returns!$B$6:$B$509)*Inputs!$B$6 | E25: =STDEV(Returns!$B$6:$B$509)*SQRT(Inputs!$B$6) | F25: =SLOPE(Returns!$B$6:$B$509,Returns!$L$6:$L$509) | G25: 1.212 | H25: =CORREL(Returns!$B$6:$B$509,Returns!$L$6:$L$509)
A26: =Inputs!A11 | B26: =Inputs!C11 | C26: =Inputs!D11 | D26: =AVERAGE(Returns!$C$6:$C$509)*Inputs!$B$6 | E26: =STDEV(Returns!$C$6:$C$509)*SQRT(Inputs!$B$6) | F26: =SLOPE(Returns!$C$6:$C$509,Returns!$L$6:$L$509) | G26: 1.188 | H26: =CORREL(Returns!$C$6:$C$509,Returns!$L$6:$L$509)
A27: =Inputs!A12 | B27: =Inputs!C12 | C27: =Inputs!D12 | D27: =AVERAGE(Returns!$D$6:$D$509)*Inputs!$B$6 | E27: =STDEV(Returns!$D$6:$D$509)*SQRT(Inputs!$B$6) | F27: =SLOPE(Returns!$D$6:$D$509,Returns!$L$6:$L$509) | G27: 1.1 | H27: =CORREL(Returns!$D$6:$D$509,Returns!$L$6:$L$509)
A28: =Inputs!A13 | B28: =Inputs!C13 | C28: =Inputs!D13 | D28: =AVERAGE(Returns!$E$6:$E$509)*Inputs!$B$6 | E28: =STDEV(Returns!$E$6:$E$509)*SQRT(Inputs!$B$6) | F28: =SLOPE(Returns!$E$6:$E$509,Returns!$L$6:$L$509) | G28: 0.491 | H28: =CORREL(Returns!$E$6:$E$509,Returns!$L$6:$L$509)
A29: =Inputs!A14 | B29: =Inputs!C14 | C29: =Inputs!D14 | D29: =AVERAGE(Returns!$F$6:$F$509)*Inputs!$B$6 | E29: =STDEV(Returns!$F$6:$F$509)*SQRT(Inputs!$B$6) | F29: =SLOPE(Returns!$F$6:$F$509,Returns!$L$6:$L$509) | G29: 0.829 | H29: =CORREL(Returns!$F$6:$F$509,Returns!$L$6:$L$509)
A30: =Inputs!A15 | B30: =Inputs!C15 | C30: =Inputs!D15 | D30: =AVERAGE(Returns!$G$6:$G$509)*Inputs!$B$6 | E30: =STDEV(Returns!$G$6:$G$509)*SQRT(Inputs!$B$6) | F30: =SLOPE(Returns!$G$6:$G$509,Returns!$L$6:$L$509) | G30: 0.511 | H30: =CORREL(Returns!$G$6:$G$509,Returns!$L$6:$L$509)
A31: =Inputs!A16 | B31: =Inputs!C16 | C31: =Inputs!D16 | D31: =AVERAGE(Returns!$H$6:$H$509)*Inputs!$B$6 | E31: =STDEV(Returns!$H$6:$H$509)*SQRT(Inputs!$B$6) | F31: =SLOPE(Returns!$H$6:$H$509,Returns!$L$6:$L$509) | G31: 1.184 | H31: =CORREL(Returns!$H$6:$H$509,Returns!$L$6:$L$509)
A32: =Inputs!A17 | B32: =Inputs!C17 | C32: =Inputs!D17 | D32: =AVERAGE(Returns!$I$6:$I$509)*Inputs!$B$6 | E32: =STDEV(Returns!$I$6:$I$509)*SQRT(Inputs!$B$6) | F32: =SLOPE(Returns!$I$6:$I$509,Returns!$L$6:$L$509) | G32: 0.64 | H32: =CORREL(Returns!$I$6:$I$509,Returns!$L$6:$L$509)
A33: =Inputs!A18 | B33: =Inputs!C18 | C33: =Inputs!D18 | D33: =AVERAGE(Returns!$J$6:$J$509)*Inputs!$B$6 | E33: =STDEV(Returns!$J$6:$J$509)*SQRT(Inputs!$B$6) | F33: =SLOPE(Returns!$J$6:$J$509,Returns!$L$6:$L$509) | G33: 1.081 | H33: =CORREL(Returns!$J$6:$J$509,Returns!$L$6:$L$509)
A34: =Inputs!A19 | B34: =Inputs!C19 | C34: =Inputs!D19 | D34: =AVERAGE(Returns!$K$6:$K$509)*Inputs!$B$6 | E34: =STDEV(Returns!$K$6:$K$509)*SQRT(Inputs!$B$6) | F34: =SLOPE(Returns!$K$6:$K$509,Returns!$L$6:$L$509) | G34: 0.421 | H34: =CORREL(Returns!$K$6:$K$509,Returns!$L$6:$L$509)
A35: Weighted beta check (should equal B13) | F35: =SUMPRODUCT(C25:C34,F25:F34)
A38: Correlation matrix (daily returns)
B39: =Inputs!A10 | C39: =Inputs!A11 | D39: =Inputs!A12 | E39: =Inputs!A13 | F39: =Inputs!A14 | G39: =Inputs!A15 | H39: =Inputs!A16 | I39: =Inputs!A17 | J39: =Inputs!A18 | K39: =Inputs!A19
A40: =Inputs!A10 | B40: =CORREL(Returns!$B$6:$B$509,Returns!$B$6:$B$509) | C40: =CORREL(Returns!$B$6:$B$509,Returns!$C$6:$C$509) | D40: =CORREL(Returns!$B$6:$B$509,Returns!$D$6:$D$509) | E40: =CORREL(Returns!$B$6:$B$509,Returns!$E$6:$E$509) | F40: =CORREL(Returns!$B$6:$B$509,Returns!$F$6:$F$509) | G40: =CORREL(Returns!$B$6:$B$509,Returns!$G$6:$G$509) | H40: =CORREL(Returns!$B$6:$B$509,Returns!$H$6:$H$509) | I40: =CORREL(Returns!$B$6:$B$509,Returns!$I$6:$I$509) | J40: =CORREL(Returns!$B$6:$B$509,Returns!$J$6:$J$509) | K40: =CORREL(Returns!$B$6:$B$509,Returns!$K$6:$K$509)
A41: =Inputs!A11 | B41: =CORREL(Returns!$C$6:$C$509,Returns!$B$6:$B$509) | C41: =CORREL(Returns!$C$6:$C$509,Returns!$C$6:$C$509) | D41: =CORREL(Returns!$C$6:$C$509,Returns!$D$6:$D$509) | E41: =CORREL(Returns!$C$6:$C$509,Returns!$E$6:$E$509) | F41: =CORREL(Returns!$C$6:$C$509,Returns!$F$6:$F$509) | G41: =CORREL(Returns!$C$6:$C$509,Returns!$G$6:$G$509) | H41: =CORREL(Returns!$C$6:$C$509,Returns!$H$6:$H$509) | I41: =CORREL(Returns!$C$6:$C$509,Returns!$I$6:$I$509) | J41: =CORREL(Returns!$C$6:$C$509,Returns!$J$6:$J$509) | K41: =CORREL(Returns!$C$6:$C$509,Returns!$K$6:$K$509)
A42: =Inputs!A12 | B42: =CORREL(Returns!$D$6:$D$509,Returns!$B$6:$B$509) | C42: =CORREL(Returns!$D$6:$D$509,Returns!$C$6:$C$509) | D42: =CORREL(Returns!$D$6:$D$509,Returns!$D$6:$D$509) | E42: =CORREL(Returns!$D$6:$D$509,Returns!$E$6:$E$509) | F42: =CORREL(Returns!$D$6:$D$509,Returns!$F$6:$F$509) | G42: =CORREL(Returns!$D$6:$D$509,Returns!$G$6:$G$509) | H42: =CORREL(Returns!$D$6:$D$509,Returns!$H$6:$H$509) | I42: =CORREL(Returns!$D$6:$D$509,Returns!$I$6:$I$509) | J42: =CORREL(Returns!$D$6:$D$509,Returns!$J$6:$J$509) | K42: =CORREL(Returns!$D$6:$D$509,Returns!$K$6:$K$509)
A43: =Inputs!A13 | B43: =CORREL(Returns!$E$6:$E$509,Returns!$B$6:$B$509) | C43: =CORREL(Returns!$E$6:$E$509,Returns!$C$6:$C$509) | D43: =CORREL(Returns!$E$6:$E$509,Returns!$D$6:$D$509) | E43: =CORREL(Returns!$E$6:$E$509,Returns!$E$6:$E$509) | F43: =CORREL(Returns!$E$6:$E$509,Returns!$F$6:$F$509) | G43: =CORREL(Returns!$E$6:$E$509,Returns!$G$6:$G$509) | H43: =CORREL(Returns!$E$6:$E$509,Returns!$H$6:$H$509) | I43: =CORREL(Returns!$E$6:$E$509,Returns!$I$6:$I$509) | J43: =CORREL(Returns!$E$6:$E$509,Returns!$J$6:$J$509) | K43: =CORREL(Returns!$E$6:$E$509,Returns!$K$6:$K$509)
A44: =Inputs!A14 | B44: =CORREL(Returns!$F$6:$F$509,Returns!$B$6:$B$509) | C44: =CORREL(Returns!$F$6:$F$509,Returns!$C$6:$C$509) | D44: =CORREL(Returns!$F$6:$F$509,Returns!$D$6:$D$509) | E44: =CORREL(Returns!$F$6:$F$509,Returns!$E$6:$E$509) | F44: =CORREL(Returns!$F$6:$F$509,Returns!$F$6:$F$509) | G44: =CORREL(Returns!$F$6:$F$509,Returns!$G$6:$G$509) | H44: =CORREL(Returns!$F$6:$F$509,Returns!$H$6:$H$509) | I44: =CORREL(Returns!$F$6:$F$509,Returns!$I$6:$I$509) | J44: =CORREL(Returns!$F$6:$F$509,Returns!$J$6:$J$509) | K44: =CORREL(Returns!$F$6:$F$509,Returns!$K$6:$K$509)
A45: =Inputs!A15 | B45: =CORREL(Returns!$G$6:$G$509,Returns!$B$6:$B$509) | C45: =CORREL(Returns!$G$6:$G$509,Returns!$C$6:$C$509) | D45: =CORREL(Returns!$G$6:$G$509,Returns!$D$6:$D$509) | E45: =CORREL(Returns!$G$6:$G$509,Returns!$E$6:$E$509) | F45: =CORREL(Returns!$G$6:$G$509,Returns!$F$6:$F$509) | G45: =CORREL(Returns!$G$6:$G$509,Returns!$G$6:$G$509) | H45: =CORREL(Returns!$G$6:$G$509,Returns!$H$6:$H$509) | I45: =CORREL(Returns!$G$6:$G$509,Returns!$I$6:$I$509) | J45: =CORREL(Returns!$G$6:$G$509,Returns!$J$6:$J$509) | K45: =CORREL(Returns!$G$6:$G$509,Returns!$K$6:$K$509)
...

Sheet Sector_Stats
A1: Sector performance (equal-weighted sector portfolios, full history)
A2: Source: sql/queries/q2_sector_performance.sql. Data source: yfinance+fred
A4: sector | B4: ann_return_pct | C4: ann_vol_pct | D4: return_to_risk | E4: worst_day_pct | F4: rank_by_return_to_risk
A5: Technology | B5: 36.32 | C5: 27.68 | D5: 1.31 | E5: -15.37 | F5: 1
A6: Consumer Discretionary | B6: 23.66 | C6: 23.48 | D6: 1.01 | E6: -14.25 | F6: 2
A7: Health Care | B7: 15.75 | C7: 17.65 | D7: 0.89 | E7: -9.9 | F7: 3
A8: Communication | B8: 16.94 | C8: 19.09 | D8: 0.89 | E8: -9.39 | F8: 4
A9: Consumer Staples | B9: 12.86 | C9: 15.3 | D9: 0.84 | E9: -8.9 | F9: 5
A10: Materials | B10: 15.79 | C10: 21.21 | D10: 0.74 | E10: -14.48 | F10: 6
A11: Financials | B11: 17.61 | C11: 25.59 | D11: 0.69 | E11: -13.73 | F11: 7
A12: Industrials | B12: 14.38 | C12: 23.38 | D12: 0.62 | E12: -12.47 | F12: 8
A13: Utilities | B13: 12.27 | C13: 20.11 | D13: 0.61 | E13: -11.74 | F13: 9
A14: Real Estate | B14: 13.65 | C14: 23.39 | D14: 0.58 | E14: -16.22 | F14: 10
A15: Energy | B15: 9.59 | C15: 30.59 | D15: 0.31 | E15: -19.96 | F15: 11

Sheet Regime_Analysis
A1: Sector behaviour by prior-day VIX regime
A2: Source: sql/queries/q6_regime_performance.sql. Data source: yfinance+fred
A4: Annualised return (%)
A5: sector | B5: 1 Low (<15) | C5: 2 Mid (15-25) | D5: 3 High (25+)
A6: Communication | B6: 21.4 | C6: 11.5 | D6: 24.4
A7: Consumer Discretionary | B7: 20.4 | C7: 19 | D7: 49.3
A8: Consumer Staples | B8: 11.7 | C8: 13.6 | D8: 13.3
A9: Energy | B9: -6.1 | C9: 20.9 | D9: 11.7
A10: Financials | B10: 21.5 | C10: 12.1 | D10: 26.7
A11: Health Care | B11: 15.2 | C11: 9.4 | D11: 40.1
A12: Industrials | B12: 7.4 | C12: 15.9 | D12: 28.1
A13: Materials | B13: 12.9 | C13: 8.3 | D13: 50.6
A14: Real Estate | B14: 12.7 | C14: 15.9 | D14: 7.9
A15: Technology | B15: 27.2 | C15: 32.8 | D15: 73.8
A16: Utilities | B16: 6.4 | C16: 17.7 | D16: 8.8
A19: Annualised volatility (%)
A20: sector | B20: 1 Low (<15) | C20: 2 Mid (15-25) | D20: 3 High (25+)
A21: Communication | B21: 12.4 | C21: 17.8 | D21: 33.3
A22: Consumer Discretionary | B22: 14.5 | C22: 22 | D22: 41.6
A23: Consumer Staples | B23: 9.7 | C23: 13.3 | D23: 28.6
A24: Energy | B24: 17.4 | C24: 28 | D24: 56.6
A25: Financials | B25: 15.6 | C25: 23.2 | D25: 46.8
A26: Health Care | B26: 11.9 | C26: 16.5 | D26: 30.2
A27: Industrials | B27: 13.5 | C27: 20.5 | D27: 44.6
A28: Materials | B28: 14.6 | C28: 18.8 | D28: 37.8
A29: Real Estate | B29: 16.3 | C29: 20.3 | D29: 42.4
A30: Technology | B30: 18.7 | C30: 26.4 | D30: 46.3
A31: Utilities | B31: 13.9 | C31: 16.7 | D31: 37.9

Sheet Model_Results
A1: Volatility forecasting and vol-target backtest (SPY)
A2: Data source: yfinance+fred
A3: Lower QLIKE / MSE is better. DM stat < 0 means better than GARCH. Walk-forward, refit quarterly.
A5: model | B5: QLIKE | C5: MSE | D5: MZ_R2 | E5: DM_stat_vs_GARCH | F5: DM_pvalue
A6: GARCH(1,1)-t | B6: 0.94528055 | C6: 25.783851 | D6: 0.27157275
A7: VIX bucket | B7: 1.0301231 | C7: 37.20748 | D7: 0.026635979 | E7: 1.5108328 | F7: 0.13083106
A8: EWMA | B8: 1.0305578 | C8: 29.408374 | D8: 0.16348861 | E8: 3.2303365 | F8: 0.001236446
A9: Rolling 21d | B9: 1.078778 | C9: 31.440915 | D9: 0.13667689 | E9: 4.2167931 | F9: 2.4780116e-05
A10: HMM 3-state | B10: 1.0874218 | C10: 34.778874 | D10: 0.024236254 | E10: 1.3979496 | F10: 0.1621282
A11: HMM 2-state | B11: 1.1598179 | C11: 34.586544 | D11: 0.017276175 | E11: 1.6111657 | F11: 0.10714361
A14: QLIKE by prior-day VIX bucket
A15: model | B15: VIX 15-25 | C15: VIX 25+ | D15: VIX<15
A16: EWMA | B16: 1.0624637 | C16: 2.5105329 | D16: -0.017421782
A17: GARCH(1,1)-t | B17: 0.98020738 | C17: 2.3653286 | D17: -0.069435321
A18: HMM 2-state | B18: 1.0097331 | C18: 3.4784193 | D18: -0.056565953
A19: HMM 3-state | B19: 0.96261156 | C19: 3.2033948 | D19: -0.048512756
A20: Rolling 21d | B20: 1.1291568 | C20: 2.568649 | D20: -0.015036445
A21: VIX bucket | B21: 0.9634893 | C21: 2.9308079 | D21: -0.086941121
A24: Volatility-targeting backtest
A25: strategy | B25: CAGR | C25: Ann. vol | D25: Sharpe | E25: Max drawdown | F25: Calmar | G25: Avg SPY weight | H25: Turnover / yr
A26: Buy & hold SPY | B26: 0.14186699 | C26: 0.19466097 | D26: 0.64774904 | E26: -0.33717254 | F26: 0.42075487 | G26: 1 | H26: 0
A27: Vol target: EWMA | B27: 0.089110527 | C27: 0.10244866 | D27: 0.63479997 | E27: -0.12781527 | F27: 0.69718216 | G27: 0.6963754 | H27: 4.4369958
A28: Vol target: GARCH(1,1)-t | B28: 0.093670948 | C28: 0.09989402 | D28: 0.69026858 | E28: -0.12224239 | F28: 0.7662722 | G28: 0.70522012 | H28: 11.585378
A29: Vol target: HMM 2-state | B29: 0.089709075 | C29: 0.10790349 | D29: 0.61310218 | E29: -0.19541085 | F29: 0.45907928 | G29: 0.68514571 | H29: 13.496737
A30: Vol target: HMM 3-state | B30: 0.089260362 | C30: 0.10773712 | D30: 0.61007865 | E30: -0.17587874 | F30: 0.50751081 | G30: 0.6994453 | H30: 12.932819
